<?xml version="1.0" ?>
<sdf version="1.11"> 
    <world name="current_world">
        <physics name="1ms" type="ignored">
            <max_step_size>0.0006</max_step_size>
            <real_time_factor>1000.0</real_time_factor>
        </physics>
        <plugin
            filename="gz-sim-physics-system"
            name="gz::sim::systems::Physics">
        </plugin>
        <plugin
            filename="gz-sim-user-commands-system"
            name="gz::sim::systems::UserCommands">
        </plugin>
        <plugin
            filename="gz-sim-scene-broadcaster-system"
            name="gz::sim::systems::SceneBroadcaster">
        </plugin> 
        <plugin
            filename="gz-sim-contact-system"
            name="gz::sim::systems::SceneBroadcaster">
        </plugin>              
    <gui fullscreen="0">  
    <camera name="ortho">
    	<pose>0 0 1 0 1.5708 1.5708</pose>
        <projection_type>orthographic</projection_type>
    </camera>
	<!-- 3D scene -->
	<plugin filename="MinimalScene" name="3D View">
	    <gz-gui>
		<title>3D View</title>
		<property type="bool" key="showTitleBar">false</property>
		<property type="string" key="state">docked</property>
	    </gz-gui>
	    <engine>ogre</engine>
	    <scene>scene</scene>
	    <ambient_light>0.4 0.4 0.4</ambient_light>
	    <background_color>0.8 0.8 0.8</background_color>
	</plugin>
	<!-- Plugins that add functionality to the scene -->
	<plugin filename="EntityContextMenuPlugin" name="Entity context menu">
	    <gz-gui>
		<property key="state" type="string">floating</property>
		<property key="width" type="double">5</property>
		<property key="height" type="double">5</property>
		<property key="showTitleBar" type="bool">false</property>
	    </gz-gui>
	</plugin>
	<plugin filename="GzSceneManager" name="Scene Manager">
	    <gz-gui>
		<property key="resizable" type="bool">false</property>
		<property key="width" type="double">5</property>
		<property key="height" type="double">5</property>
		<property key="state" type="string">floating</property>
		<property key="showTitleBar" type="bool">false</property>
	    </gz-gui>
	</plugin>
	<plugin filename="InteractiveViewControl" name="Interactive view control">
	    <gz-gui>
		<property key="resizable" type="bool">false</property>
		<property key="width" type="double">5</property>
		<property key="height" type="double">5</property>
		<property key="state" type="string">floating</property>
		<property key="showTitleBar" type="bool">false</property>
	    </gz-gui>
	</plugin>
	<plugin filename="MarkerManager" name="Marker manager">
	    <gz-gui>
		<property key="resizable" type="bool">false</property>
		<property key="width" type="double">5</property>
		<property key="height" type="double">5</property>
		<property key="state" type="string">floating</property>
		<property key="showTitleBar" type="bool">false</property>
	    </gz-gui>
	</plugin>
	<plugin filename="SelectEntities" name="Select Entities">
	    <gz-gui>
		<property key="resizable" type="bool">false</property>
		<property key="width" type="double">5</property>
		<property key="height" type="double">5</property>
		<property key="state" type="string">floating</property>
		<property key="showTitleBar" type="bool">false</property>
	    </gz-gui>
	</plugin>
	<plugin filename="VisualizationCapabilities" name="Visualization Capabilities">
	    <gz-gui>
		<property key="resizable" type="bool">false</property>
		<property key="width" type="double">5</property>
		<property key="height" type="double">5</property>
		<property key="state" type="string">floating</property>
		<property key="showTitleBar" type="bool">false</property>
	    </gz-gui>
	</plugin>
	<!-- World control -->
	<plugin filename="WorldControl" name="World control">
	    <gz-gui>
		<title>World control</title>
		<property type="bool" key="showTitleBar">false</property>
		<property type="bool" key="resizable">false</property>
		<property type="double" key="height">72</property>
		<property type="double" key="z">1</property>
		<property type="string" key="state">floating</property>
		<anchors target="3D View">
		    <line own="left" target="left"/>
		    <line own="bottom" target="bottom"/>
		</anchors>
	    </gz-gui>
	    <play_pause>true</play_pause>
	    <step>true</step>
	    <start_paused>true</start_paused>
	    <use_event>true</use_event>
	</plugin>
	<!-- World statistics -->
	<plugin filename="WorldStats" name="World stats">
	    <gz-gui>
		<title>World stats</title>
		<property type="bool" key="showTitleBar">false</property>
		<property type="bool" key="resizable">false</property>
		<property type="double" key="height">110</property>
		<property type="double" key="width">290</property>
		<property type="double" key="z">1</property>
		<property type="string" key="state">floating</property>
		<anchors target="3D View">
		    <line own="right" target="right"/>
		    <line own="bottom" target="bottom"/>
		</anchors>
	    </gz-gui>
	    <sim_time>true</sim_time>
	    <real_time>true</real_time>
	    <real_time_factor>true</real_time_factor>
	    <iterations>true</iterations>
	</plugin>
	<!-- Translate / rotate -->
	<plugin filename="TransformControl" name="Transform control">
	    <gz-gui>
		<property key="resizable" type="bool">false</property>
		<property key="x" type="double">0</property>
		<property key="y" type="double">50</property>
		<property key="width" type="double">250</property>
		<property key="height" type="double">50</property>
		<property key="state" type="string">floating</property>
		<property key="showTitleBar" type="bool">false</property>
		<property key="cardBackground" type="string">#777777</property>
	    </gz-gui>
	</plugin>
	<!-- Inspector -->
	<plugin filename="ComponentInspector" name="Component inspector">
	    <gz-gui>
		<property type="bool" key="showTitleBar">false</property>
		<property type="string" key="state">docked</property>
	    </gz-gui>
	</plugin>
	<!-- Entity tree -->
	<plugin filename="EntityTree" name="Entity tree">
	    <gz-gui>
		<property type="bool" key="showTitleBar">false</property>
		<property type="string" key="state">docked</property>
	    </gz-gui>
	</plugin> 
      <plugin filename="MarkerManager" name="Marker manager">
        <gz-gui>
          <property key="resizable" type="bool">false</property>
          <property key="width" type="double">5</property>
          <property key="height" type="double">5</property>
          <property key="state" type="string">floating</property>
          <property key="showTitleBar" type="bool">false</property>
        </gz-gui>
      </plugin>

      <!-- Visualize Contacts -->
      <plugin filename="VisualizeContacts" name="Visualize Contacts">
        <gz-gui>
          <property key="state" type="string">docked</property>
        </gz-gui>
      </plugin>	    
      </gui>
	<light type="directional" name="sun">
	    <cast_shadows>false</cast_shadows>
	    <pose>0 0 10 0 0 0</pose>
	    <diffuse>0.8 0.8 0.8 1</diffuse>
	    <specular>0.2 0.2 0.2 1</specular>
	    <attenuation>
		<range>1000</range>
		<constant>0.9</constant>
		<linear>0.01</linear>
		<quadratic>0.001</quadratic>
	    </attenuation>
	    <direction>-0.5 0.1 -0.9</direction>
	</light>   
	
	
	   
<model name="modGround">
	<static>true</static>
	<link name="lnkGround">
		<collision name="collision">
			<geometry>
			    <plane>
			    <normal>0 0 1</normal>
			    </plane>
			</geometry>
		</collision>
		<visual name="visual">
			<geometry>
			    <plane>
			    <normal>0 0 1</normal>
			    <size>100 100</size>
			    </plane>
			</geometry>
		<material>
		    <ambient>0.8 0.8 0.8 1</ambient>
		    <diffuse>0.8 0.8 0.8 1</diffuse>
		    <specular>0.8 0.8 0.8 1</specular>
		</material>
		</visual>
	</link>
</model>	    
        
        <model name="modLeg">
    	<link name="lnkL">
		<pose>0 0 .7 0 0 0</pose>
		<inertial>
		  <mass>2.483</mass>
		  <inertia>
		    <ixx>0.025957</ixx>  <iyy>0.025957</iyy>
		    <izz>0.00005006</izz>
		    <ixy>0</ixy>
		    <ixz>0</ixz>
		    <iyz>0</iyz>
		  </inertia>
		</inertial>
		<visual name="visual">
		  <geometry>
		    <cylinder>
		      <radius>0.00635</radius>
		      <length>0.3540125</length>
		    </cylinder>
		  </geometry>
		  <material>
		    <ambient>0.5 0.5 0.5 1</ambient>  <diffuse>0.5 0.5 0.5 1</diffuse>
		    <specular>0.1 0.1 0.1 1</specular>
		  </material>
		</visual>
	</link>

    	<link name="lnkTibia">
		<pose relative_to="frmL">0 0 -0.178 0 0 0</pose>
		<inertial>
		  <mass>2.483</mass>
		  <inertia>
		    <ixx>0.025957</ixx>  <iyy>0.025957</iyy>
		    <izz>0.00005006</izz>
		    <ixy>0</ixy>
		    <ixz>0</ixz>
		    <iyz>0</iyz>
		  </inertia>
		</inertial>
		<visual name="visual">
		  <geometry>
		    <cylinder>
		      <radius>0.00635</radius>
		      <length>0.3540125</length>
		    </cylinder>
		  </geometry>
		  <material>
		    <ambient>1 0 0 1</ambient>  <diffuse>1 0 0 1</diffuse>
		    <specular>0.1 0.1 0.1 1</specular>
		  </material>
		</visual>
	</link>
	
	<link name="lnkMetatarsal">
		<pose relative_to="frmPosteriorAnkle">0 0 -0.06235 0 0 0</pose>
		<inertial>
		  <mass>.23</mass>
		  <inertia>
		    <ixx>0.000311</ixx>  <iyy>0.000311</iyy>
		    <izz>0.000005</izz>
		    <ixy>0</ixy>
		    <ixz>0</ixz>
		    <iyz>0</iyz>
		  </inertia>
		</inertial>
		<visual name="visual">
		  <geometry>
		    <cylinder>
		      <radius>0.00635</radius>
		      <length>0.12700</length>
		    </cylinder>
		  </geometry>
		  <material>
		    <ambient>0.5 0.5 0.5 1</ambient>  <diffuse>0.5 0.5 0.5 1</diffuse>
		    <specular>0.1 0.1 0.1 1</specular>
		  </material>
		</visual>
	</link>	 
		
	<link name="lnkCalcaneus">
		<pose relative_to="frmAnteriorAnkle">0 0 -0.0366617 0 0 0</pose>
		<inertial>
		  <mass>.132</mass>
		  <inertia>
		    <ixx>0.00006</ixx>  <iyy>0.00006</iyy>
		    <izz>0.000003</izz>
		    <ixy>0</ixy>
		    <ixz>0</ixz>
		    <iyz>0</iyz>
		  </inertia>
		</inertial>		
		<visual name="visual">
		  <geometry>
		    <cylinder>
		      <radius>0.00635</radius>
		      <length>0.0733235</length>
		    </cylinder>
		  </geometry>
		  <material>
		    <ambient>0.5 0.5 0.5 1</ambient>  <diffuse>0.5 0.5 0.5 1</diffuse>
		    <specular>0.1 0.1 0.1 1</specular>
		  </material>
		</visual>
	</link>

	<link name="lnkHeel">
		<pose relative_to="lnkCalcaneus">0 0 -0.0366617 .523599 0 0</pose>
		<inertial>
		  <mass>.09</mass>
		  <inertia> 
		    <ixx>0.000020564</ixx> <iyy>0.000020564</iyy><izz>0.00003871</izz>		  
		    <ixy>0</ixy>
		    <ixz>0</ixz>
		    <iyz>0</iyz>
		  </inertia>
		</inertial>
		<collision name="collision">
		  <geometry>
		    <box>
		      <size>0.0508 0.0508 0.0127</size> </box>
		  </geometry>
		   <surface>
		    <friction>
		      <ode>
			<mu>0.5</mu>
			<mu2>0.5</mu2>
		      </ode>
		    </friction>
		  </surface>
		</collision>
		<visual name="visual">
		  <geometry>
		    <box>
		      <size>0.0508 0.0508 0.0127</size>
		    </box>
		  </geometry>
		  <material>
			<ambient>0 0 1 1</ambient>  
			<diffuse>0 0 1 1</diffuse>
			<specular>0.1 0.1 0.1 1</specular>
		  </material>
		</visual>
	</link>
	
	<link name="lnkPlantar">
		<pose relative_to="lnkMetatarsal">-0.009525 0 -0.0635 -1.0472 0 0</pose>
		<inertial>
		  <mass>.1</mass>
		  <inertia> 
		    <ixx>0.00002285</ixx> <iyy>0.000042</iyy><izz>0.00006216</izz>		  
		    <ixy>0</ixy>
		    <ixz>0</ixz>
		    <iyz>0</iyz>
		  </inertia>
		</inertial>
		<collision name="collision">
		  <geometry>
		    <box>
		      <size>0.06985 0.0508 0.0127</size> </box>
		  </geometry>
		   <surface>
		    <friction>
		      <ode>
			<mu>0.5</mu>
			<mu2>0.5</mu2>
		      </ode>
		    </friction>
		  </surface>
		</collision>
		<visual name="visual">
		  <geometry>
		    <box>
		      <size>0.06985 0.0508 0.0127</size>
		    </box>
		  </geometry>
		  <material>
			<ambient>0 0 1 1</ambient>  
			<diffuse>0 0 1 1</diffuse>
			<specular>0.1 0.1 0.1 1</specular>
		  </material>
		</visual>
	</link>		

	<joint name="weld_temp1" type="fixed">
		<parent>lnkL</parent>
		<child>lnkTibia</child>
		<pose>0 0 0 0 0 0</pose> 		
	</joint>
		
	<joint name="weld1" type="fixed">
		<parent>lnkCalcaneus</parent>
		<child>lnkMetatarsal</child>
		<pose>0 0 0 0 0 0</pose> 		
	</joint>
					
	<frame name="frmL" attached_to="lnkL">
		<pose>0 0 -0.1770063  0 0 0</pose>		
	</frame>	

	<frame name="frmAnkle" attached_to="lnkTibia">
		<pose>0 0 -0.1770063  0 0 0</pose>		
	</frame>
	
	<frame name="frmPosteriorAnkle" attached_to="lnkTibia">
		<pose>0 0 -0.1770063  1.0472 0 0</pose>		
	</frame>

	<frame name="frmAnteriorAnkle" attached_to="lnkTibia">
		<pose>0 0 -0.1770063 -0.5236 0 0</pose>		
	</frame>

	<frame name="frmHeelTop" attached_to="lnkHeel">
		<pose>0 0 0.000127 0 0 0</pose>		
	</frame>
	
	<frame name="frmPlantarTop" attached_to="lnkPlantar">
		<pose>0 0 0.000127 0 0 0</pose>		
	</frame>	

	<joint name="jntAnkle" type="revolute">
		<parent>lnkTibia</parent>
		<child>lnkCalcaneus</child>
		<pose relative_to="frmPosteriorAnkle">0 0 0 0 0 0</pose> 
		<axis>
		  <xyz>1 0 0</xyz>
		</axis>		
	</joint>

	<joint name="jntPlantar" type="universal">
		<parent>lnkMetatarsal</parent>
		<child>lnkPlantar</child>
		<pose relative_to="frmPlantarTop">0 0 0 0 0 0</pose> 
		<axis>
		  <xyz>0 1 0</xyz>
		</axis>
		<axis2>
		  <xyz>1 0 0</xyz>
		</axis2>		
	</joint>
	
	<joint name="jntHeel" type="universal">
		<parent>lnkCalcaneus</parent>
		<child>lnkHeel</child>
		<pose relative_to="frmHeelTop">0 0 0 0 0 0</pose> 
		<axis>
		  <xyz>0 1 0</xyz>
		</axis>
		<axis2>
		  <xyz>1 0 0</xyz>
		</axis2>		
	</joint>
		
      </model>      
    </world>
</sdf>
